<sdf version='1.6'>
  <model name='mpo_700'>
    <link name='base_link'>
      <pose frame=''>0 0 0 0 -0 0</pose>
      <inertial>
        <pose frame=''>-0 0 1e-06 0 -0 0</pose>
        <mass>140</mass>
        <inertia>
          <ixx>7.80014</ixx>
          <ixy>7.94833e-05</ixy>
          <ixz>1.06509e-05</ixz>
          <iyy>7.80026</iyy>
          <iyz>-6.93282e-08</iyz>
          <izz>7.80035</izz>
        </inertia>
      </inertial>
      <collision name='base_link_fixed_joint_lump__base_footprint_collision'>
        <pose frame=''>0 0 0 0 0 -1.571</pose>
        <geometry>
          <mesh>
            <scale>0.001 0.001 0.001</scale>
            <uri>model://neo_simulation2/robots/mpo_700/meshes/MPO-700-BODY.dae</uri>
          </mesh>
        </geometry>
      </collision>
      <collision name='base_link_fixed_joint_lump__camera_link_collision_1'>
        <pose frame=''>-0.228 0.015 0.461 0 -0 3.14159</pose>
        <geometry>
          <box>
            <size>0.05 0.05 0.05</size>
          </box>
        </geometry>
      </collision>
      <collision name='base_link_fixed_joint_lump__docking_adapter_link_collision_2'>
        <pose frame=''>-0.3 0 0.32 0 0 -1.57</pose>
        <geometry>
          <mesh>
            <scale>0.1 0.1 0.1</scale>
            <uri>model://neo_simulation2/robots/mpo_700/meshes/MPO-700-charge-port.dae</uri>
          </mesh>
        </geometry>
      </collision>
      <collision name='base_link_fixed_joint_lump__lidar_1_link_collision_3'>
        <pose frame=''>0.337932 0.288067 0.283 -1.57319 -0 0.79</pose>
        <geometry>
          <mesh>
            <scale>0.001 0.001 0.001</scale>
            <uri>model://neo_simulation2/robots/mpo_700/meshes/SICK-MICROSCAN3.dae</uri>
          </mesh>
        </geometry>
        <surface>
          <contact>
            <ode/>
          </contact>
          <friction>
            <ode/>
          </friction>
        </surface>
      </collision>
      <collision name='base_link_fixed_joint_lump__lidar_2_link_collision_4'>
        <pose frame=''>-0.337932 -0.288067 0.283 -1.57319 -0 -2.35319</pose>
        <geometry>
          <mesh>
            <scale>0.001 0.001 0.001</scale>
            <uri>model://neo_simulation2/robots/mpo_700/meshes/SICK-MICROSCAN3.dae</uri>
          </mesh>
        </geometry>
        <surface>
          <contact>
            <ode/>
          </contact>
          <friction>
            <ode/>
          </friction>
        </surface>
      </collision>
      <visual name='base_link_fixed_joint_lump__base_footprint_visual'>
        <pose frame=''>0 0 0 0 0 -1.571</pose>
        <geometry>
          <mesh>
            <scale>0.001 0.001 0.001</scale>
            <uri>model://neo_simulation2/robots/mpo_700/meshes/MPO-700-BODY.dae</uri>
          </mesh>
        </geometry>
      </visual>
      <visual name='base_link_fixed_joint_lump__camera_link_visual_1'>
        <pose frame=''>-0.228 0.0325 0.461 1.5708 0 -1.5708</pose>
        <geometry>
          <mesh>
            <scale>1 1 1</scale>
            <uri>model://neo_simulation2/robots/mpo_700/meshes/d435.dae</uri>
          </mesh>
        </geometry>
      </visual>
      <visual name='base_link_fixed_joint_lump__docking_adapter_link_visual_2'>
        <pose frame=''>-0.3 0 0.32 0 0 -1.57</pose>
        <geometry>
          <mesh>
            <scale>0.1 0.1 0.1</scale>
            <uri>model://neo_simulation2/robots/mpo_700/meshes/MPO-700-charge-port.dae</uri>
          </mesh>
        </geometry>
      </visual>
      <visual name='base_link_fixed_joint_lump__lidar_1_link_visual_3'>
        <pose frame=''>0.337932 0.288067 0.283 -1.57319 -0 0.79</pose>
        <geometry>
          <mesh>
            <scale>0.001 0.001 0.001</scale>
            <uri>model://neo_simulation2/robots/mpo_700/meshes/SICK-MICROSCAN3.dae</uri>
          </mesh>
        </geometry>
        <material>
          <script>
            <uri>__default__</uri>
            <name>__default__</name>
          </script>
        </material>
      </visual>
      <visual name='base_link_fixed_joint_lump__lidar_2_link_visual_4'>
        <pose frame=''>-0.337932 -0.288067 0.283 -1.57319 -0 -2.35319</pose>
        <geometry>
          <mesh>
            <scale>0.001 0.001 0.001</scale>
            <uri>model://neo_simulation2/robots/mpo_700/meshes/SICK-MICROSCAN3.dae</uri>
          </mesh>
        </geometry>
        <material>
          <script>
            <uri>__default__</uri>
            <name>__default__</name>
          </script>
        </material>
      </visual>
      <velocity_decay/>
      <self_collide>0</self_collide>
      <gravity>1</gravity>
      <velocity_decay/>
      <sensor name='lidar_1_sensor' type='ray'>
        <visualize>0</visualize>
        <update_rate>40</update_rate>
        <ray>
          <scan>
            <horizontal>
              <samples>720</samples>
              <resolution>1</resolution>
              <min_angle>-1.48</min_angle>
              <max_angle>1.48</max_angle>
            </horizontal>
          </scan>
          <range>
            <min>0.1</min>
            <max>30</max>
            <resolution>0.05</resolution>
          </range>
          <noise>
            <type>gaussian</type>
            <mean>0</mean>
            <stddev>0.01</stddev>
          </noise>
        </ray>
        <pose frame=''>0.338 0.288 0.223 3.14 0 0.79</pose>
      </sensor>
      <gravity>1</gravity>
      <velocity_decay/>
      <sensor name='lidar_2_sensor' type='ray'>
        <visualize>0</visualize>
        <update_rate>40</update_rate>
        <ray>
          <scan>
            <horizontal>
              <samples>720</samples>
              <resolution>1</resolution>
              <min_angle>-1.48</min_angle>
              <max_angle>1.48</max_angle>
            </horizontal>
          </scan>
          <range>
            <min>0.1</min>
            <max>30</max>
            <resolution>0.05</resolution>
          </range>
          <noise>
            <type>gaussian</type>
            <mean>0</mean>
            <stddev>0.01</stddev>
          </noise>
        </ray>
        <pose frame=''>-0.338 -0.288 0.223 3.14 -0 -2.35319</pose>
      </sensor>
    </link>
    <link name='mpo_700_caster_back_left_link'>
      <pose frame=''>-0.24 0.18 0.22 0 -0 3.14</pose>
      <inertial>
        <pose frame=''>0 0 0 0 -0 0</pose>
        <mass>12.7</mass>
        <inertia>
          <ixx>0.272581</ixx>
          <ixy>0</ixy>
          <ixz>0</ixz>
          <iyy>0.272581</iyy>
          <iyz>0</iyz>
          <izz>0.272581</izz>
        </inertia>
      </inertial>
      <collision name='mpo_700_caster_back_left_link_collision'>
        <pose frame=''>0 0 0 0 -0 0</pose>
        <geometry>
          <mesh>
            <scale>0.001 0.001 0.001</scale>
            <uri>model://neo_simulation2/robots/mpo_700/meshes/MPO-700-HEAD.dae</uri>
          </mesh>
        </geometry>
      </collision>
      <visual name='mpo_700_caster_back_left_link_visual'>
        <pose frame=''>0 0 0 0 -0 0</pose>
        <geometry>
          <mesh>
            <scale>0.001 0.001 0.001</scale>
            <uri>model://neo_simulation2/robots/mpo_700/meshes/MPO-700-HEAD.dae</uri>
          </mesh>
        </geometry>
      </visual>
    </link>
    <joint name='mpo_700_caster_back_left_joint' type='revolute'>
      <child>mpo_700_caster_back_left_link</child>
      <parent>base_link</parent>
      <axis>
        <xyz>0 0 1</xyz>
        <limit>
          <lower>-1e+16</lower>
          <upper>1e+16</upper>
          <effort>1000</effort>
          <velocity>6.5</velocity>
        </limit>
        <dynamics>
          <spring_reference>0</spring_reference>
          <spring_stiffness>0</spring_stiffness>
        </dynamics>
        <use_parent_model_frame>1</use_parent_model_frame>
      </axis>
    </joint>
    <link name='mpo_700_wheel_back_left_link'>
      <pose frame=''>-0.240072 0.135 0.1 0 -0 3.14</pose>
      <inertial>
        <pose frame=''>0 0 0 0 -0 0</pose>
        <mass>1.2</mass>
        <inertia>
          <ixx>0.110421</ixx>
          <ixy>0</ixy>
          <ixz>0</ixz>
          <iyy>0.110421</iyy>
          <iyz>0</iyz>
          <izz>0.110421</izz>
        </inertia>
      </inertial>
      <collision name='mpo_700_wheel_back_left_link_collision'>
        <pose frame=''>0 0 0 0 -0 0</pose>
        <geometry>
          <sphere>
            <radius>0.09</radius>
          </sphere>
        </geometry>
      </collision>
      <visual name='mpo_700_wheel_back_left_link_visual'>
        <pose frame=''>0 0 0 0 -0 3.14</pose>
        <geometry>
          <mesh>
            <scale>0.001 0.001 0.001</scale>
            <uri>model://neo_simulation2/robots/mpo_700/meshes/MPO-700-WHEEL.dae</uri>
          </mesh>
        </geometry>
      </visual>
    </link>
    <joint name='mpo_700_wheel_back_left_joint' type='revolute'>
      <child>mpo_700_wheel_back_left_link</child>
      <parent>mpo_700_caster_back_left_link</parent>
      <axis>
        <xyz>0.001593 0.999999 0</xyz>
        <limit>
          <lower>-1e+16</lower>
          <upper>1e+16</upper>
          <effort>1000</effort>
          <velocity>20.5</velocity>
        </limit>
        <dynamics>
          <spring_reference>0</spring_reference>
          <spring_stiffness>0</spring_stiffness>
        </dynamics>
        <use_parent_model_frame>1</use_parent_model_frame>
      </axis>
    </joint>
    <link name='mpo_700_caster_back_right_link'>
      <pose frame=''>-0.24 -0.18 0.22 0 -0 0</pose>
      <inertial>
        <pose frame=''>0 0 0 0 -0 0</pose>
        <mass>12.7</mass>
        <inertia>
          <ixx>0.272581</ixx>
          <ixy>0</ixy>
          <ixz>0</ixz>
          <iyy>0.272581</iyy>
          <iyz>0</iyz>
          <izz>0.272581</izz>
        </inertia>
      </inertial>
      <collision name='mpo_700_caster_back_right_link_collision'>
        <pose frame=''>0 0 0 0 -0 3.14</pose>
        <geometry>
          <mesh>
            <scale>0.001 0.001 0.001</scale>
            <uri>model://neo_simulation2/robots/mpo_700/meshes/MPO-700-HEAD.dae</uri>
          </mesh>
        </geometry>
      </collision>
      <visual name='mpo_700_caster_back_right_link_visual'>
        <pose frame=''>0 0 0 0 -0 3.14</pose>
        <geometry>
          <mesh>
            <scale>0.001 0.001 0.001</scale>
            <uri>model://neo_simulation2/robots/mpo_700/meshes/MPO-700-HEAD.dae</uri>
          </mesh>
        </geometry>
      </visual>
    </link>
    <joint name='mpo_700_caster_back_right_joint' type='revolute'>
      <child>mpo_700_caster_back_right_link</child>
      <parent>base_link</parent>
      <axis>
        <xyz>0 0 1</xyz>
        <limit>
          <lower>-1e+16</lower>
          <upper>1e+16</upper>
          <effort>1000</effort>
          <velocity>6.5</velocity>
        </limit>
        <dynamics>
          <spring_reference>0</spring_reference>
          <spring_stiffness>0</spring_stiffness>
        </dynamics>
        <use_parent_model_frame>1</use_parent_model_frame>
      </axis>
    </joint>
    <link name='mpo_700_wheel_back_right_link'>
      <pose frame=''>-0.24 -0.225 0.1 0 -0 3.14</pose>
      <inertial>
        <pose frame=''>0 0 0 0 -0 0</pose>
        <mass>1.2</mass>
        <inertia>
          <ixx>0.110421</ixx>
          <ixy>0</ixy>
          <ixz>0</ixz>
          <iyy>0.110421</iyy>
          <iyz>0</iyz>
          <izz>0.110421</izz>
        </inertia>
      </inertial>
      <collision name='mpo_700_wheel_back_right_link_collision'>
        <pose frame=''>0 0 0 0 -0 0</pose>
        <geometry>
          <sphere>
            <radius>0.09</radius>
          </sphere>
        </geometry>
      </collision>
      <visual name='mpo_700_wheel_back_right_link_visual'>
        <pose frame=''>0 0 0 0 -0 3.14</pose>
        <geometry>
          <mesh>
            <scale>0.001 0.001 0.001</scale>
            <uri>model://neo_simulation2/robots/mpo_700/meshes/MPO-700-WHEEL.dae</uri>
          </mesh>
        </geometry>
      </visual>
    </link>
    <joint name='mpo_700_wheel_back_right_joint' type='revolute'>
      <child>mpo_700_wheel_back_right_link</child>
      <parent>mpo_700_caster_back_right_link</parent>
      <axis>
        <xyz>0.001593 0.999999 0</xyz>
        <limit>
          <lower>-1e+16</lower>
          <upper>1e+16</upper>
          <effort>1000</effort>
          <velocity>20.5</velocity>
        </limit>
        <dynamics>
          <spring_reference>0</spring_reference>
          <spring_stiffness>0</spring_stiffness>
        </dynamics>
        <use_parent_model_frame>1</use_parent_model_frame>
      </axis>
    </joint>
    <link name='mpo_700_caster_front_left_link'>
      <pose frame=''>0.24 0.18 0.22 0 -0 3.14</pose>
      <inertial>
        <pose frame=''>0 0 0 0 -0 0</pose>
        <mass>12.7</mass>
        <inertia>
          <ixx>0.272581</ixx>
          <ixy>0</ixy>
          <ixz>0</ixz>
          <iyy>0.272581</iyy>
          <iyz>0</iyz>
          <izz>0.272581</izz>
        </inertia>
      </inertial>
      <collision name='mpo_700_caster_front_left_link_collision'>
        <pose frame=''>0 0 0 0 -0 0</pose>
        <geometry>
          <mesh>
            <scale>0.001 0.001 0.001</scale>
            <uri>model://neo_simulation2/robots/mpo_700/meshes/MPO-700-HEAD.dae</uri>
          </mesh>
        </geometry>
      </collision>
      <visual name='mpo_700_caster_front_left_link_visual'>
        <pose frame=''>0 0 0 0 -0 0</pose>
        <geometry>
          <mesh>
            <scale>0.001 0.001 0.001</scale>
            <uri>model://neo_simulation2/robots/mpo_700/meshes/MPO-700-HEAD.dae</uri>
          </mesh>
        </geometry>
      </visual>
    </link>
    <joint name='mpo_700_caster_front_left_joint' type='revolute'>
      <child>mpo_700_caster_front_left_link</child>
      <parent>base_link</parent>
      <axis>
        <xyz>0 0 1</xyz>
        <limit>
          <lower>-1e+16</lower>
          <upper>1e+16</upper>
          <effort>1000</effort>
          <velocity>6.5</velocity>
        </limit>
        <dynamics>
          <spring_reference>0</spring_reference>
          <spring_stiffness>0</spring_stiffness>
        </dynamics>
        <use_parent_model_frame>1</use_parent_model_frame>
      </axis>
    </joint>
    <link name='mpo_700_wheel_front_left_link'>
      <pose frame=''>0.239928 0.135 0.1 0 -0 3.14</pose>
      <inertial>
        <pose frame=''>0 0 0 0 -0 0</pose>
        <mass>1.2</mass>
        <inertia>
          <ixx>0.110421</ixx>
          <ixy>0</ixy>
          <ixz>0</ixz>
          <iyy>0.110421</iyy>
          <iyz>0</iyz>
          <izz>0.110421</izz>
        </inertia>
      </inertial>
      <collision name='mpo_700_wheel_front_left_link_collision'>
        <pose frame=''>0 0 0 0 -0 0</pose>
        <geometry>
          <sphere>
            <radius>0.09</radius>
          </sphere>
        </geometry>
      </collision>
      <visual name='mpo_700_wheel_front_left_link_visual'>
        <pose frame=''>0 0 0 0 -0 3.14</pose>
        <geometry>
          <mesh>
            <scale>0.001 0.001 0.001</scale>
            <uri>model://neo_simulation2/robots/mpo_700/meshes/MPO-700-WHEEL.dae</uri>
          </mesh>
        </geometry>
      </visual>
    </link>
    <joint name='mpo_700_wheel_front_left_joint' type='revolute'>
      <child>mpo_700_wheel_front_left_link</child>
      <parent>mpo_700_caster_front_left_link</parent>
      <axis>
        <xyz>0.001593 0.999999 0</xyz>
        <limit>
          <lower>-1e+16</lower>
          <upper>1e+16</upper>
          <effort>1000</effort>
          <velocity>20.5</velocity>
        </limit>
        <dynamics>
          <spring_reference>0</spring_reference>
          <spring_stiffness>0</spring_stiffness>
        </dynamics>
        <use_parent_model_frame>1</use_parent_model_frame>
      </axis>
    </joint>
    <link name='mpo_700_caster_front_right_link'>
      <pose frame=''>0.24 -0.18 0.22 0 -0 0</pose>
      <inertial>
        <pose frame=''>0 0 0 0 -0 0</pose>
        <mass>12.7</mass>
        <inertia>
          <ixx>0.272581</ixx>
          <ixy>0</ixy>
          <ixz>0</ixz>
          <iyy>0.272581</iyy>
          <iyz>0</iyz>
          <izz>0.272581</izz>
        </inertia>
      </inertial>
      <collision name='mpo_700_caster_front_right_link_collision'>
        <pose frame=''>0 0 0 0 -0 3.14</pose>
        <geometry>
          <mesh>
            <scale>0.001 0.001 0.001</scale>
            <uri>model://neo_simulation2/robots/mpo_700/meshes/MPO-700-HEAD.dae</uri>
          </mesh>
        </geometry>
      </collision>
      <visual name='mpo_700_caster_front_right_link_visual'>
        <pose frame=''>0 0 0 0 -0 3.14</pose>
        <geometry>
          <mesh>
            <scale>0.001 0.001 0.001</scale>
            <uri>model://neo_simulation2/robots/mpo_700/meshes/MPO-700-HEAD.dae</uri>
          </mesh>
        </geometry>
      </visual>
    </link>
    <joint name='mpo_700_caster_front_right_joint' type='revolute'>
      <child>mpo_700_caster_front_right_link</child>
      <parent>base_link</parent>
      <axis>
        <xyz>0 0 1</xyz>
        <limit>
          <lower>-1e+16</lower>
          <upper>1e+16</upper>
          <effort>1000</effort>
          <velocity>6.5</velocity>
        </limit>
        <dynamics>
          <spring_reference>0</spring_reference>
          <spring_stiffness>0</spring_stiffness>
        </dynamics>
        <use_parent_model_frame>1</use_parent_model_frame>
      </axis>
    </joint>
    <link name='mpo_700_wheel_front_right_link'>
      <pose frame=''>0.24 -0.225 0.1 0 -0 3.14</pose>
      <inertial>
        <pose frame=''>0 0 0 0 -0 0</pose>
        <mass>1.2</mass>
        <inertia>
          <ixx>0.110421</ixx>
          <ixy>0</ixy>
          <ixz>0</ixz>
          <iyy>0.110421</iyy>
          <iyz>0</iyz>
          <izz>0.110421</izz>
        </inertia>
      </inertial>
      <collision name='mpo_700_wheel_front_right_link_collision'>
        <pose frame=''>0 0 0 0 -0 0</pose>
        <geometry>
          <sphere>
            <radius>0.09</radius>
          </sphere>
        </geometry>
      </collision>
      <visual name='mpo_700_wheel_front_right_link_visual'>
        <pose frame=''>0 0 0 0 -0 3.14</pose>
        <geometry>
          <mesh>
            <scale>0.001 0.001 0.001</scale>
            <uri>model://neo_simulation2/robots/mpo_700/meshes/MPO-700-WHEEL.dae</uri>
          </mesh>
        </geometry>
      </visual>
    </link>
    <joint name='mpo_700_wheel_front_right_joint' type='revolute'>
      <child>mpo_700_wheel_front_right_link</child>
      <parent>mpo_700_caster_front_right_link</parent>
      <axis>
        <xyz>0.001593 0.999999 0</xyz>
        <limit>
          <lower>-1e+16</lower>
          <upper>1e+16</upper>
          <effort>1000</effort>
          <velocity>20.5</velocity>
        </limit>
        <dynamics>
          <spring_reference>0</spring_reference>
          <spring_stiffness>0</spring_stiffness>
        </dynamics>
        <use_parent_model_frame>1</use_parent_model_frame>
      </axis>
    </joint>
  </model>
</sdf>
